Workbook

Sheet READ_ME
B2: Smart VAs LLC — Monthly Financial Model
B4: Currency | C4: USD. All amounts in whole US dollars unless a line is labelled as a percentage, a ratio or a day count.
B5: Basis of accounting | C5: Accrual, per the seller general ledger and confirmed in the QOE engagement correspondence.
B6: Period covered | C6: June 2024 through June 2026 (25 consecutive months).
B7: Prepared for | C7: GP Partners — Quality of Earnings engagement.
B9: Scope
C11: The engagement email chain descopes the original request. The most recent instruction is to focus on the monthly financial statements only, with the trial balance rebuild, KPI set, labour-versus-revenue breakdown and the software/systems inventory deferred to a separate project. This workbook therefore contains the monthly income statement, balance sheet and statement of cash flows, together with the supporting schedules required by the finance memo, plus the month-over-month working capital schedule and the DSO section requested in the chain.
B13: Items deliberately excluded (deferred to the separate project)
C14: Annual trial balance rebuild; KPI/ratio set (gross profit margin against all labour, net profit margin, ROA, current ratio, cash ratio, D/E, D/A); the direct-labour-and-COGS-against-revenue tab; and the schedule defining the software, apps, programs and systems tied to the business.
B16: Source data
B18: Trial balance | C18: TB_20240531.pdf — Smart VAs LLC trial balance as of 31 May 2024. Transcribed in full; debits and credits both total 424,147.41, which agrees to the source document.
B19: General ledger | C19: 1_GeneralLedger_MoM_Combined.pdf — 925 pages, comprising 25 separate monthly ledger extracts concatenated into one file.
B20: Rows extracted | C20: 15,699 ledger lines. This figure was verified against an independent count of every record block in the PDF: 15,699 blocks, none missing a transaction date, none missing an amount.
B22: How the model is wired
B24: GL Data tab | C24: The only input tab. Column D holds the opening trial balance at 31 May 2024; columns E onward hold monthly ledger activity by account. All figures are debit-positive and credit-negative. Blue text marks a hardcoded input.
B25: Monthly Financials tab | C25: Every figure is a formula. Teal text marks a value pulled across from the GL Data tab; black marks a calculation within the tab. Nothing on this tab is typed in.
B26: Account mapping | C26: Each of the 76 accounts in the ledger and trial balance maps to exactly one statement line — no account is unmapped and none is counted twice. Statement lines pull their accounts by name, so adding an account to GL Data with an existing statement line flows through automatically.
B27: Recalculation | C27: Iterative calculation is enabled, as required by the marketing memo, because the modeled line of credit interest is circular (interest feeds net income, which feeds cash, which feeds the draw).
B29: Ledger sign conventions (fitted, not assumed)
C31: The ledger export reports each line as the change in that account's own natural balance rather than as an explicit debit or credit. Three accounts do not follow the convention their trial balance position implies, and the treatment below was established by testing which reading makes the ledger balance, not by assumption:
B32: Owner's Pay & Personal Expenses | C32: Behaves as credit-natural in the ledger. Confirmed by the 1 January 2025 and 1 January 2026 year-end entries, which close this account into Retained Earnings and only balance under this reading.
B33: Discounts and Refund | C33: Behave as credit-natural, i.e. reported as negative revenue rather than as debit-side contra-revenue.
B34: Result | C34: Under these conventions the ledger balances to (123.60) in total across all 25 months and all 15,699 lines. Eleven individual months balance to within one dollar.
B36: Accounts Receivable — derived figure
C38: This is the one number in the model that the ledger does not directly support, and it should be read as derived rather than reported.
C39: The ledger export omits the accounts receivable side of both customer invoices and customer payments. An invoice appears only as the revenue credit and the merchant fee debit; the matching payment appears only as the cash debit. The two net correctly when both fall in the same month — a customer billed 1,000 with a 29.30 merchant fee shows 970.70 of cash — but a receivable outstanding at a month end has no ledger line.
C40: The residual imbalance in each month is therefore booked to accounts receivable, on the GL Data tab, as a row labelled "A/R timing plug (derived)". It is a formula, not a hardcode, so it stays consistent if the underlying data changes.
B41: Size of the adjustment | C41: Small and self-correcting. Receivables open at 533 per the trial balance and close at 656 in June 2026, moving within a band of roughly plus or minus a few thousand dollars.
B42: Known exception | C42: November and December 2025 show a negative derived receivable of (6,579) and (2,769). This is a timing artefact of the missing ledger lines, not a customer credit balance. A ledger export that includes the A/R distribution lines would resolve it.
B44: Judgements and presentation choices
B46: Merchant fees | C46: Credit card fees are presented within operating expenses under "Fees and Charges" rather than as a cost of revenue. They run at roughly 2 to 3 per cent of revenue and are invoice-linked, so a reviewer may prefer them above the gross profit line. Reclassifying them would reduce gross margin and leave net income unchanged.
B47: Credit cards in cash flow | C47: Credit card balances are treated as operating rather than financing, on the basis that the cards are used to settle operating expenses rather than as a funding source.
B48: Intercompany balances | C48: The "Meet 5-star VAs" sub-accounts and "Intercompany - Meet 5-Star Pros" are carried as current assets (amounts due from affiliates), consistent with their position in the trial balance. These are related-party balances and warrant separate diligence.
B49: Income taxes | C49: No entity-level income tax expense is recorded in the ledger, consistent with a pass-through LLC. The tax schedule shows payroll tax and taxes and licences only.
B50: Depreciation | C50: Accumulated depreciation shows no movement across the 25 months. Fixed assets are carried at the trial balance amount throughout and no depreciation expense is recorded in the period.
B52: Line of credit mechanic
C54: The finance memo requires that a negative ending cash balance trigger a line of credit draw and the corresponding interest expense. The mechanic is built and live in the model.
B55: Status in this period | C55: It does not trigger. Cash is positive in every month, rising from 23,371 at June 2024 to 87,174 at June 2026. The modeled draw is therefore nil throughout and the interest expense it produces is nil.
B56: Assumptions | C56: Minimum cash balance and the annual interest rate are blue input cells in Schedule 5. They are modelling assumptions, not figures taken from the ledger.
B58: Checks built into the model
...

Sheet GL Data
A1: Smart VAs LLC
A2: General Ledger — Monthly Activity by Account (debit-positive / credit-negative)
A3: Currency: USD
A5: GL / TB Account | B5: Statement Line | C5: Class | D5: Opening TB 5/31/2024 | E5: Jun-24 | F5: Jul-24 | G5: Aug-24 | H5: Sep-24 | I5: Oct-24 | J5: Nov-24 | K5: Dec-24 | L5: Jan-25 | M5: Feb-25 | N5: Mar-25 | O5: Apr-25 | P5: May-25 | Q5: Jun-25 | R5: Jul-25 | S5: Aug-25 | T5: Sep-25 | U5: Oct-25 | V5: Nov-25 | W5: Dec-25 | X5: Jan-26 | Y5: Feb-26 | Z5: Mar-26 | AA5: Apr-26 | AB5: May-26 | AC5: Jun-26
A6: AMEX Credit Card | B6: AMEX Credit Card | C6: L | D6: -1252.3 | E6: -140.91 | F6: -576.74 | G6: -44.8 | H6: 316.99 | I6: 439.82 | J6: -562.91 | K6: -549.43 | L6: 576.2 | M6: 359.96 | N6: 193.95 | O6: 167.91 | P6: 50.42 | Q6: -1037.24 | R6: 853.4 | S6: 229.53 | T6: -2140.47 | U6: -1224.05 | V6: 2444.01 | W6: 410.33 | X6: -2494.02 | Y6: -1279.24 | Z6: 4556.23 | AA6: -374.82 | AB6: -9.45 | AC6: -44.7
A7: Accounts Receivable | B7: Accounts Receivable | C7: A | D7: 532.65 | E7: 0 | F7: 0 | G7: 0 | H7: 0 | I7: 0 | J7: 0 | K7: 0 | L7: 0 | M7: 0 | N7: 16.99 | O7: -16.99 | P7: 0 | Q7: 0 | R7: 0 | S7: 284.4 | T7: -284.4 | U7: 0 | V7: 0 | W7: 0 | X7: 0 | Y7: 0 | Z7: 0 | AA7: 0 | AB7: 0 | AC7: 0
A8: Accrued Retirement | B8: Accrued Retirement | C8: L | D8: -1289.88 | E8: 859.92 | F8: 45 | G8: 45 | H8: 0 | I8: 339.96 | J8: -339.96 | K8: -339.96 | L8: -339.96 | M8: -339.96 | N8: -339.96 | O8: -339.96 | P8: -339.96 | Q8: 2379.72 | R8: 0 | S8: 0 | T8: -339.96 | U8: 339.96 | V8: 0 | W8: 0 | X8: 0 | Y8: 0 | Z8: 0 | AA8: 0 | AB8: 0 | AC8: 0
A9: Accum Depreciation | B9: Accumulated Depreciation | C9: XA | D9: -12754.39 | E9: 0 | F9: 0 | G9: 0 | H9: 0 | I9: 0 | J9: 0 | K9: 0 | L9: 0 | M9: 0 | N9: 0 | O9: 0 | P9: 0 | Q9: 0 | R9: 0 | S9: 0 | T9: 0 | U9: 0 | V9: 0 | W9: 0 | X9: 0 | Y9: 0 | Z9: 0 | AA9: 0 | AB9: 0 | AC9: 0
A10: Advances subject to Liquidation | B10: Advances subject to Liquidation | C10: A | D10: 302.46 | E10: 44.55 | F10: 98.1 | G10: 26.14 | H10: -223.76 | I10: -16.16 | J10: 38.46 | K10: 333.97 | L10: -266.85 | M10: -176.12 | N10: -265.74 | O10: 245.61 | P10: -22.84 | Q10: 0 | R10: 0 | S10: -76.61 | T10: -41.21 | U10: 0 | V10: 0 | W10: 0 | X10: 0 | Y10: 0 | Z10: 0 | AA10: 0 | AB10: 0 | AC10: 0
A11: Advances to Contractors | B11: Advances to Contractors | C11: A | D11: 414.91 | E11: -223.5 | F11: 680.46 | G11: -89.25 | H11: 840.65 | I11: -515.86 | J11: 818.26 | K11: -442.03 | L11: -200.99 | M11: -177.67 | N11: 0.55 | O11: 115.28 | P11: 117.99 | Q11: -233.02 | R11: 194.68 | S11: 490.52 | T11: -405.44 | U11: -164.17 | V11: 201.48 | W11: 42.3 | X11: -65.6 | Y11: -725.36 | Z11: -296.43 | AA11: -189.39 | AB11: -82.72 | AC11: -105.65
A12: Amex Delta Credit Card | B12: Amex Delta Credit Card | C12: L | D12: -14166 | E12: -2433.24 | F12: 5490.63 | G12: 2062.26 | H12: 2036.7 | I12: -226.17 | J12: -58.21 | K12: -177.44 | L12: -2532.27 | M12: 102.24 | N12: -2014.36 | O12: 79.67 | P12: 10.31 | Q12: 2752.99 | R12: 290.81 | S12: 4062.32 | T12: 3088.99 | U12: 215.98 | V12: 168.65 | W12: -635.98 | X12: -2371.96 | Y12: 2940.77 | Z12: 98.78 | AA12: -62.08 | AB12: 143.75 | AC12: -929.51
A13: Charitable Contributions | B13: Charitable Contributions | C13: E | D13: 0 | E13: 0 | F13: 0 | G13: 0 | H13: 0 | I13: 0 | J13: 0 | K13: 0 | L13: 0 | M13: 0 | N13: 0 | O13: 0 | P13: 0 | Q13: 0 | R13: 0 | S13: 0 | T13: 0 | U13: 100 | V13: 0 | W13: 200 | X13: 100 | Y13: 100 | Z13: 100 | AA13: 100 | AB13: 100 | AC13: 100
A14: Chase Credit Card 4 (1892) | B14: Chase Credit Card 4 (1892) | C14: L | D14: -1889.3 | E14: 453.73 | F14: -75.17 | G14: -444.22 | H14: -487.91 | I14: -3093.67 | J14: 2133.37 | K14: -2431.52 | L14: -2362.43 | M14: -413.58 | N14: 31.53 | O14: 1733.81 | P14: -722.67 | Q14: 486.36 | R14: 1527.01 | S14: 4752.36 | T14: -649.46 | U14: -604.13 | V14: 1209.32 | W14: -963.81 | X14: 928.67 | Y14: -168.14 | Z14: 108.73 | AA14: -529.69 | AB14: 380.18 | AC14: -649.5
A15: Christmas Expenses Fund | B15: Christmas Expenses Fund | C15: L | D15: 0 | E15: 0 | F15: 0 | G15: -357.73 | H15: -450.57 | I15: -433.84 | J15: -427.7 | K15: 1669.84 | L15: 0 | M15: 0 | N15: 0 | O15: 0 | P15: 0 | Q15: 0 | R15: -807.41 | S15: 0 | T15: 0 | U15: 0 | V15: -684.16 | W15: 1491.57 | X15: 0 | Y15: 0 | Z15: 0 | AA15: 0 | AB15: 0 | AC15: 0
A16: Cost of Services:Contractors - Client Hours | B16: Contractors - Client Hours | C16: E | D16: 109119.97 | E16: 19394.04 | F16: 18266.33 | G16: 20915.87 | H16: 20818.06 | I16: 22253.11 | J16: 21849.94 | K16: 18495.84 | L16: 17320.71 | M16: 19492.66 | N16: 18326.41 | O16: 20629.36 | P16: 21453.48 | Q16: 21869.94 | R16: 21439.57 | S16: 25115.95 | T16: 24359.34 | U16: 24557.02 | V16: 23570.34 | W16: 21932.71 | X16: 21068.2 | Y16: 24105.05 | Z16: 21329.32 | AA16: 23432.68 | AB16: 22967.15 | AC16: 22258.75
A17: Cost of Services:Contractors - Idle Time | B17: Contractors - Idle Time | C17: E | D17: 6474.17 | E17: 1166.36 | F17: 817.49 | G17: 899.16 | H17: 668.06 | I17: 763.66 | J17: 1547.32 | K17: 1484.27 | L17: 985.85 | M17: 856.37 | N17: 1072.85 | O17: 617.86 | P17: 534.89 | Q17: 732.63 | R17: 1252.22 | S17: 1004.05 | T17: 1130.93 | U17: 974.1 | V17: 1300.18 | W17: 1260.22 | X17: 1062.81 | Y17: 1311.04 | Z17: 1443.68 | AA17: 1059.39 | AB17: 1295.65 | AC17: 701.82
... A81: Wise Fund | B81: Wise Fund | C81: A | D81: 9.83 | E81: -3.63 | F81: 0 | G81: -3.65 | H81: 0 | I81: 0 | J81: 0 | K81: 0 | L81: 0 | M81: 0 | N81: 0 | O81: 0 | P81: 0 | Q81: 0 | R81: 0 | S81: 0 | T81: 0 | U81: 0 | V81: 0 | W81: 0 | X81: 0 | Y81: 0 | Z81: 0 | AA81: 0 | AB81: 0 | AC81: 0
A82: A/R timing plug (derived — see READ_ME) | B82: Accounts Receivable | C82: A | D82: 0 | E82: =-SUM(E6:E81) -> -2.0374813e-12 | F82: =-SUM(F6:F81) -> -3.7471137e-12 | G82: =-SUM(G6:G81) -> 715.46 | H82: =-SUM(H6:H81) -> 901.14 | I82: =-SUM(I6:I81) -> 867.68 | J82: =-SUM(J6:J81) -> 855.4 | K82: =-SUM(K6:K81) -> -3216.08 | L82: =-SUM(L6:L81) -> 1030.42 | ... AC82: =-SUM(AC6:AC81) -> -3.6379788e-12
A84: Opening equity at 5/31/2024 (balancing, per TB) | D84: 35592.74

Sheet Monthly Financials
A1: Smart VAs LLC
A2: Monthly Financial Statements — Income Statement, Balance Sheet & Statement of Cash Flows
A3: Currency: USD (all amounts in whole US dollars)
A4: Period: June 2024 – June 2026 (25 months) | Basis: Accrual | Source: Seller general ledger & 5/31/2024 trial balance
A6: INCOME STATEMENT
B7: TB 5/31/24 | C7: Jun-24 | D7: Jul-24 | E7: Aug-24 | F7: Sep-24 | G7: Oct-24 | H7: Nov-24 | I7: Dec-24 | J7: Jan-25 | K7: Feb-25 | L7: Mar-25 | M7: Apr-25 | N7: May-25 | O7: Jun-25 | P7: Jul-25 | Q7: Aug-25 | R7: Sep-25 | S7: Oct-25 | T7: Nov-25 | U7: Dec-25 | V7: Jan-26 | W7: Feb-26 | X7: Mar-26 | Y7: Apr-26 | Z7: May-26 | AA7: Jun-26
A8: Revenue
A9: Service Revenue | C9: =-SUMIFS('GL Data'!$E:$E,'GL Data'!$B:$B,$A9) -> 68051.11 | D9: =-SUMIFS('GL Data'!$F:$F,'GL Data'!$B:$B,$A9) -> 81627.01 | E9: =-SUMIFS('GL Data'!$G:$G,'GL Data'!$B:$B,$A9) -> 72116.4 | F9: =-SUMIFS('GL Data'!$H:$H,'GL Data'!$B:$B,$A9) -> 71580.32 | G9: =-SUMIFS('GL Data'!$I:$I,'GL Data'!$B:$B,$A9) -> 75657.75 | H9: =-SUMIFS('GL Data'!$J:$J,'GL Data'!$B:$B,$A9) -> 71033.56 | I9: =-SUMIFS('GL Data'!$K:$K,'GL Data'!$B:$B,$A9) -> 70881.91 | J9: =-SUMIFS('GL Data'!$L:$L,'GL Data'!$B:$B,$A9) -> 66313.39 | K9: =-SUMIFS('GL Data'!$M:$M,'GL Data'!$B:$B,$A9) -> 61919.05 | L9: =-SUMIFS('GL Data'!$N:$N,'GL Data'!$B:$B,$A9) -> 69485.32 | M9: =-SUMIFS('GL Data'!$O:$O,'GL Data'!$B:$B,$A9) -> 77448.33 | N9: =-SUMIFS('GL Data'!$P:$P,'GL Data'!$B:$B,$A9) -> 83272.41 | O9: =-SUMIFS('GL Data'!$Q:$Q,'GL Data'!$B:$B,$A9) -> 55987.5 | P9: =-SUMIFS('GL Data'!$R:$R,'GL Data'!$B:$B,$A9) -> 97281.23 | Q9: =-SUMIFS('GL Data'!$S:$S,'GL Data'!$B:$B,$A9) -> 65230.76 | R9: =-SUMIFS('GL Data'!$T:$T,'GL Data'!$B:$B,$A9) -> 78706.91 | S9: =-SUMIFS('GL Data'!$U:$U,'GL Data'!$B:$B,$A9) -> 98271.75 | T9: =-SUMIFS('GL Data'!$V:$V,'GL Data'!$B:$B,$A9) -> 83283.37 | U9: =-SUMIFS('GL Data'!$W:$W,'GL Data'!$B:$B,$A9) -> 81117.9 | V9: =-SUMIFS('GL Data'!$X:$X,'GL Data'!$B:$B,$A9) -> 95842.24 | W9: =-SUMIFS('GL Data'!$Y:$Y,'GL Data'!$B:$B,$A9) -> 65696.46 | X9: =-SUMIFS('GL Data'!$Z:$Z,'GL Data'!$B:$B,$A9) -> 69807.44 | Y9: =-SUMIFS('GL Data'!$AA:$AA,'GL Data'!$B:$B,$A9) -> 96105.92 | Z9: =-SUMIFS('GL Data'!$AB:$AB,'GL Data'!$B:$B,$A9) -> 80095.39 | AA9: =-SUMIFS('GL Data'!$AC:$AC,'GL Data'!$B:$B,$A9) -> 64477.22
A10: Smart VA Academy Revenue | C10: =-SUMIFS('GL Data'!$E:$E,'GL Data'!$B:$B,$A10) -> 8.43 | D10: =-SUMIFS('GL Data'!$F:$F,'GL Data'!$B:$B,$A10) -> 8.46 | E10: =-SUMIFS('GL Data'!$G:$G,'GL Data'!$B:$B,$A10) -> 8.5 | F10: =-SUMIFS('GL Data'!$H:$H,'GL Data'!$B:$B,$A10) -> 0 | G10: =-SUMIFS('GL Data'!$I:$I,'GL Data'!$B:$B,$A10) -> 69.91 | H10: =-SUMIFS('GL Data'!$J:$J,'GL Data'!$B:$B,$A10) -> 21.02 | I10: =-SUMIFS('GL Data'!$K:$K,'GL Data'!$B:$B,$A10) -> 30.44 | J10: =-SUMIFS('GL Data'!$L:$L,'GL Data'!$B:$B,$A10) -> 22.03 | K10: =-SUMIFS('GL Data'!$M:$M,'GL Data'!$B:$B,$A10) -> 73.41 | L10: =-SUMIFS('GL Data'!$N:$N,'GL Data'!$B:$B,$A10) -> 0 | M10: =-SUMIFS('GL Data'!$O:$O,'GL Data'!$B:$B,$A10) -> 62.46 | N10: =-SUMIFS('GL Data'!$P:$P,'GL Data'!$B:$B,$A10) -> 53.48 | O10: =-SUMIFS('GL Data'!$Q:$Q,'GL Data'!$B:$B,$A10) -> 96.66 | P10: =-SUMIFS('GL Data'!$R:$R,'GL Data'!$B:$B,$A10) -> 39.98 | Q10: =-SUMIFS('GL Data'!$S:$S,'GL Data'!$B:$B,$A10) -> 88.42 | R10: =-SUMIFS('GL Data'!$T:$T,'GL Data'!$B:$B,$A10) -> 8.69 | S10: =-SUMIFS('GL Data'!$U:$U,'GL Data'!$B:$B,$A10) -> 121.29 | T10: =-SUMIFS('GL Data'!$V:$V,'GL Data'!$B:$B,$A10) -> 8.39 | U10: =-SUMIFS('GL Data'!$W:$W,'GL Data'!$B:$B,$A10) -> 8.46 | V10: =-SUMIFS('GL Data'!$X:$X,'GL Data'!$B:$B,$A10) -> 8.41 | W10: =-SUMIFS('GL Data'!$Y:$Y,'GL Data'!$B:$B,$A10) -> 0 | X10: =-SUMIFS('GL Data'!$Z:$Z,'GL Data'!$B:$B,$A10) -> 19.82 | Y10: =-SUMIFS('GL Data'!$AA:$AA,'GL Data'!$B:$B,$A10) -> 0 | Z10: =-SUMIFS('GL Data'!$AB:$AB,'GL Data'!$B:$B,$A10) -> 0 | AA10: =-SUMIFS('GL Data'!$AC:$AC,'GL Data'!$B:$B,$A10) -> 0
A11: Unapplied Cash Payments | C11: =-SUMIFS('GL Data'!$E:$E,'GL Data'!$B:$B,$A11) -> 0 | D11: =-SUMIFS('GL Data'!$F:$F,'GL Data'!$B:$B,$A11) -> 0 | E11: =-SUMIFS('GL Data'!$G:$G,'GL Data'!$B:$B,$A11) -> 0 | F11: =-SUMIFS('GL Data'!$H:$H,'GL Data'!$B:$B,$A11) -> 0 | G11: =-SUMIFS('GL Data'!$I:$I,'GL Data'!$B:$B,$A11) -> 0 | H11: =-SUMIFS('GL Data'!$J:$J,'GL Data'!$B:$B,$A11) -> 0 | I11: =-SUMIFS('GL Data'!$K:$K,'GL Data'!$B:$B,$A11) -> 0 | J11: =-SUMIFS('GL Data'!$L:$L,'GL Data'!$B:$B,$A11) -> 0 | K11: =-SUMIFS('GL Data'!$M:$M,'GL Data'!$B:$B,$A11) -> 0 | L11: =-SUMIFS('GL Data'!$N:$N,'GL Data'!$B:$B,$A11) -> 0 | M11: =-SUMIFS('GL Data'!$O:$O,'GL Data'!$B:$B,$A11) -> 0 | N11: =-SUMIFS('GL Data'!$P:$P,'GL Data'!$B:$B,$A11) -> 0 | O11: =-SUMIFS('GL Data'!$Q:$Q,'GL Data'!$B:$B,$A11) -> 0 | P11: =-SUMIFS('GL Data'!$R:$R,'GL Data'!$B:$B,$A11) -> 0 | Q11: =-SUMIFS('GL Data'!$S:$S,'GL Data'!$B:$B,$A11) -> -741.78 | R11: =-SUMIFS('GL Data'!$T:$T,'GL Data'!$B:$B,$A11) -> 741.78 | S11: =-SUMIFS('GL Data'!$U:$U,'GL Data'!$B:$B,$A11) -> 0 | T11: =-SUMIFS('GL Data'!$V:$V,'GL Data'!$B:$B,$A11) -> 0 | U11: =-SUMIFS('GL Data'!$W:$W,'GL Data'!$B:$B,$A11) -> 0 | V11: =-SUMIFS('GL Data'!$X:$X,'GL Data'!$B:$B,$A11) -> 0 | W11: =-SUMIFS('GL Data'!$Y:$Y,'GL Data'!$B:$B,$A11) -> 0 | X11: =-SUMIFS('GL Data'!$Z:$Z,'GL Data'!$B:$B,$A11) -> 0 | Y11: =-SUMIFS('GL Data'!$AA:$AA,'GL Data'!$B:$B,$A11) -> 0 | Z11: =-SUMIFS('GL Data'!$AB:$AB,'GL Data'!$B:$B,$A11) -> 0 | AA11: =-SUMIFS('GL Data'!$AC:$AC,'GL Data'!$B:$B,$A11) -> 0
A12: Other Miscellaneous Income | C12: =-SUMIFS('GL Data'!$E:$E,'GL Data'!$B:$B,$A12) -> 0 | D12: =-SUMIFS('GL Data'!$F:$F,'GL Data'!$B:$B,$A12) -> 0 | E12: =-SUMIFS('GL Data'!$G:$G,'GL Data'!$B:$B,$A12) -> 0 | F12: =-SUMIFS('GL Data'!$H:$H,'GL Data'!$B:$B,$A12) -> 0 | G12: =-SUMIFS('GL Data'!$I:$I,'GL Data'!$B:$B,$A12) -> 0 | H12: =-SUMIFS('GL Data'!$J:$J,'GL Data'!$B:$B,$A12) -> 0 | I12: =-SUMIFS('GL Data'!$K:$K,'GL Data'!$B:$B,$A12) -> 0 | J12: =-SUMIFS('GL Data'!$L:$L,'GL Data'!$B:$B,$A12) -> 0 | K12: =-SUMIFS('GL Data'!$M:$M,'GL Data'!$B:$B,$A12) -> 0 | L12: =-SUMIFS('GL Data'!$N:$N,'GL Data'!$B:$B,$A12) -> 0 | M12: =-SUMIFS('GL Data'!$O:$O,'GL Data'!$B:$B,$A12) -> 0 | N12: =-SUMIFS('GL Data'!$P:$P,'GL Data'!$B:$B,$A12) -> 135.82 | O12: =-SUMIFS('GL Data'!$Q:$Q,'GL Data'!$B:$B,$A12) -> 0 | P12: =-SUMIFS('GL Data'!$R:$R,'GL Data'!$B:$B,$A12) -> 0 | Q12: =-SUMIFS('GL Data'!$S:$S,'GL Data'!$B:$B,$A12) -> 0 | R12: =-SUMIFS('GL Data'!$T:$T,'GL Data'!$B:$B,$A12) -> 0 | S12: =-SUMIFS('GL Data'!$U:$U,'GL Data'!$B:$B,$A12) -> 0 | T12: =-SUMIFS('GL Data'!$V:$V,'GL Data'!$B:$B,$A12) -> 0 | U12: =-SUMIFS('GL Data'!$W:$W,'GL Data'!$B:$B,$A12) -> 0 | V12: =-SUMIFS('GL Data'!$X:$X,'GL Data'!$B:$B,$A12) -> 0 | W12: =-SUMIFS('GL Data'!$Y:$Y,'GL Data'!$B:$B,$A12) -> 0 | X12: =-SUMIFS('GL Data'!$Z:$Z,'GL Data'!$B:$B,$A12) -> 0 | Y12: =-SUMIFS('GL Data'!$AA:$AA,'GL Data'!$B:$B,$A12) -> 0 | Z12: =-SUMIFS('GL Data'!$AB:$AB,'GL Data'!$B:$B,$A12) -> 0 | AA12: =-SUMIFS('GL Data'!$AC:$AC,'GL Data'!$B:$B,$A12) -> 0
A13: Discounts | C13: =-SUMIFS('GL Data'!$E:$E,'GL Data'!$B:$B,$A13) -> -1260 | D13: =-SUMIFS('GL Data'!$F:$F,'GL Data'!$B:$B,$A13) -> -1578 | E13: =-SUMIFS('GL Data'!$G:$G,'GL Data'!$B:$B,$A13) -> -1800 | F13: =-SUMIFS('GL Data'!$H:$H,'GL Data'!$B:$B,$A13) -> -2160 | G13: =-SUMIFS('GL Data'!$I:$I,'GL Data'!$B:$B,$A13) -> -1125 | H13: =-SUMIFS('GL Data'!$J:$J,'GL Data'!$B:$B,$A13) -> -1500 | I13: =-SUMIFS('GL Data'!$K:$K,'GL Data'!$B:$B,$A13) -> -2610 | J13: =-SUMIFS('GL Data'!$L:$L,'GL Data'!$B:$B,$A13) -> -750 | K13: =-SUMIFS('GL Data'!$M:$M,'GL Data'!$B:$B,$A13) -> -1500 | L13: =-SUMIFS('GL Data'!$N:$N,'GL Data'!$B:$B,$A13) -> -1050 | M13: =-SUMIFS('GL Data'!$O:$O,'GL Data'!$B:$B,$A13) -> -1410 | N13: =-SUMIFS('GL Data'!$P:$P,'GL Data'!$B:$B,$A13) -> -2328 | O13: =-SUMIFS('GL Data'!$Q:$Q,'GL Data'!$B:$B,$A13) -> -600 | P13: =-SUMIFS('GL Data'!$R:$R,'GL Data'!$B:$B,$A13) -> -1638 | Q13: =-SUMIFS('GL Data'!$S:$S,'GL Data'!$B:$B,$A13) -> -1500 | R13: =-SUMIFS('GL Data'!$T:$T,'GL Data'!$B:$B,$A13) -> -1128 | S13: =-SUMIFS('GL Data'!$U:$U,'GL Data'!$B:$B,$A13) -> -3060.5 | T13: =-SUMIFS('GL Data'!$V:$V,'GL Data'!$B:$B,$A13) -> -2556 | U13: =-SUMIFS('GL Data'!$W:$W,'GL Data'!$B:$B,$A13) -> -1728 | V13: =-SUMIFS('GL Data'!$X:$X,'GL Data'!$B:$B,$A13) -> -3804 | W13: =-SUMIFS('GL Data'!$Y:$Y,'GL Data'!$B:$B,$A13) -> -2028 | X13: =-SUMIFS('GL Data'!$Z:$Z,'GL Data'!$B:$B,$A13) -> -828 | Y13: =-SUMIFS('GL Data'!$AA:$AA,'GL Data'!$B:$B,$A13) -> -1788 | Z13: =-SUMIFS('GL Data'!$AB:$AB,'GL Data'!$B:$B,$A13) -> -2378 | AA13: =-SUMIFS('GL Data'!$AC:$AC,'GL Data'!$B:$B,$A13) -> -350
A14: Refunds | C14: =-SUMIFS('GL Data'!$E:$E,'GL Data'!$B:$B,$A14) -> -1280 | D14: =-SUMIFS('GL Data'!$F:$F,'GL Data'!$B:$B,$A14) -> -1500 | E14: =-SUMIFS('GL Data'!$G:$G,'GL Data'!$B:$B,$A14) -> -880 | F14: =-SUMIFS('GL Data'!$H:$H,'GL Data'!$B:$B,$A14) -> 0 | G14: =-SUMIFS('GL Data'!$I:$I,'GL Data'!$B:$B,$A14) -> 0 | H14: =-SUMIFS('GL Data'!$J:$J,'GL Data'!$B:$B,$A14) -> 0 | I14: =-SUMIFS('GL Data'!$K:$K,'GL Data'!$B:$B,$A14) -> 0 | J14: =-SUMIFS('GL Data'!$L:$L,'GL Data'!$B:$B,$A14) -> 0 | K14: =-SUMIFS('GL Data'!$M:$M,'GL Data'!$B:$B,$A14) -> 0 | L14: =-SUMIFS('GL Data'!$N:$N,'GL Data'!$B:$B,$A14) -> 0 | M14: =-SUMIFS('GL Data'!$O:$O,'GL Data'!$B:$B,$A14) -> -1000 | N14: =-SUMIFS('GL Data'!$P:$P,'GL Data'!$B:$B,$A14) -> -50 | O14: =-SUMIFS('GL Data'!$Q:$Q,'GL Data'!$B:$B,$A14) -> -498 | P14: =-SUMIFS('GL Data'!$R:$R,'GL Data'!$B:$B,$A14) -> -780 | Q14: =-SUMIFS('GL Data'!$S:$S,'GL Data'!$B:$B,$A14) -> -500 | R14: =-SUMIFS('GL Data'!$T:$T,'GL Data'!$B:$B,$A14) -> -598.1 | S14: =-SUMIFS('GL Data'!$U:$U,'GL Data'!$B:$B,$A14) -> -500 | T14: =-SUMIFS('GL Data'!$V:$V,'GL Data'!$B:$B,$A14) -> 0 | U14: =-SUMIFS('GL Data'!$W:$W,'GL Data'!$B:$B,$A14) -> 0 | V14: =-SUMIFS('GL Data'!$X:$X,'GL Data'!$B:$B,$A14) -> -150 | W14: =-SUMIFS('GL Data'!$Y:$Y,'GL Data'!$B:$B,$A14) -> 0 | X14: =-SUMIFS('GL Data'!$Z:$Z,'GL Data'!$B:$B,$A14) -> -2136.2 | Y14: =-SUMIFS('GL Data'!$AA:$AA,'GL Data'!$B:$B,$A14) -> -5095.99 | Z14: =-SUMIFS('GL Data'!$AB:$AB,'GL Data'!$B:$B,$A14) -> -1000 | AA14: =-SUMIFS('GL Data'!$AC:$AC,'GL Data'!$B:$B,$A14) -> 0
A15: Net Revenue | C15: =SUM(C9:C14) -> 65519.54 | D15: =SUM(D9:D14) -> 78557.47 | E15: =SUM(E9:E14) -> 69444.9 | F15: =SUM(F9:F14) -> 69420.32 | G15: =SUM(G9:G14) -> 74602.66 | H15: =SUM(H9:H14) -> 69554.58 | I15: =SUM(I9:I14) -> 68302.35 | J15: =SUM(J9:J14) -> 65585.42 | ... AA15: =SUM(AA9:AA14) -> 64127.22
A17: Cost of Services
A18: Contractors - Client Hours | C18: =SUMIFS('GL Data'!$E:$E,'GL Data'!$B:$B,$A18) -> 19394.04 | D18: =SUMIFS('GL Data'!$F:$F,'GL Data'!$B:$B,$A18) -> 18266.33 | E18: =SUMIFS('GL Data'!$G:$G,'GL Data'!$B:$B,$A18) -> 20915.87 | F18: =SUMIFS('GL Data'!$H:$H,'GL Data'!$B:$B,$A18) -> 20818.06 | G18: =SUMIFS('GL Data'!$I:$I,'GL Data'!$B:$B,$A18) -> 22253.11 | H18: =SUMIFS('GL Data'!$J:$J,'GL Data'!$B:$B,$A18) -> 21849.94 | I18: =SUMIFS('GL Data'!$K:$K,'GL Data'!$B:$B,$A18) -> 18495.84 | J18: =SUMIFS('GL Data'!$L:$L,'GL Data'!$B:$B,$A18) -> 17320.71 | K18: =SUMIFS('GL Data'!$M:$M,'GL Data'!$B:$B,$A18) -> 19492.66 | L18: =SUMIFS('GL Data'!$N:$N,'GL Data'!$B:$B,$A18) -> 18326.41 | M18: =SUMIFS('GL Data'!$O:$O,'GL Data'!$B:$B,$A18) -> 20629.36 | N18: =SUMIFS('GL Data'!$P:$P,'GL Data'!$B:$B,$A18) -> 21453.48 | O18: =SUMIFS('GL Data'!$Q:$Q,'GL Data'!$B:$B,$A18) -> 21869.94 | P18: =SUMIFS('GL Data'!$R:$R,'GL Data'!$B:$B,$A18) -> 21439.57 | Q18: =SUMIFS('GL Data'!$S:$S,'GL Data'!$B:$B,$A18) -> 25115.95 | R18: =SUMIFS('GL Data'!$T:$T,'GL Data'!$B:$B,$A18) -> 24359.34 | S18: =SUMIFS('GL Data'!$U:$U,'GL Data'!$B:$B,$A18) -> 24557.02 | T18: =SUMIFS('GL Data'!$V:$V,'GL Data'!$B:$B,$A18) -> 23570.34 | U18: =SUMIFS('GL Data'!$W:$W,'GL Data'!$B:$B,$A18) -> 21932.71 | V18: =SUMIFS('GL Data'!$X:$X,'GL Data'!$B:$B,$A18) -> 21068.2 | W18: =SUMIFS('GL Data'!$Y:$Y,'GL Data'!$B:$B,$A18) -> 24105.05 | X18: =SUMIFS('GL Data'!$Z:$Z,'GL Data'!$B:$B,$A18) -> 21329.32 | Y18: =SUMIFS('GL Data'!$AA:$AA,'GL Data'!$B:$B,$A18) -> 23432.68 | Z18: =SUMIFS('GL Data'!$AB:$AB,'GL Data'!$B:$B,$A18) -> 22967.15 | AA18: =SUMIFS('GL Data'!$AC:$AC,'GL Data'!$B:$B,$A18) -> 22258.75
A19: Contractors - Idle Time | C19: =SUMIFS('GL Data'!$E:$E,'GL Data'!$B:$B,$A19) -> 1166.36 | D19: =SUMIFS('GL Data'!$F:$F,'GL Data'!$B:$B,$A19) -> 817.49 | E19: =SUMIFS('GL Data'!$G:$G,'GL Data'!$B:$B,$A19) -> 899.16 | F19: =SUMIFS('GL Data'!$H:$H,'GL Data'!$B:$B,$A19) -> 668.06 | G19: =SUMIFS('GL Data'!$I:$I,'GL Data'!$B:$B,$A19) -> 763.66 | H19: =SUMIFS('GL Data'!$J:$J,'GL Data'!$B:$B,$A19) -> 1547.32 | I19: =SUMIFS('GL Data'!$K:$K,'GL Data'!$B:$B,$A19) -> 1484.27 | J19: =SUMIFS('GL Data'!$L:$L,'GL Data'!$B:$B,$A19) -> 985.85 | K19: =SUMIFS('GL Data'!$M:$M,'GL Data'!$B:$B,$A19) -> 856.37 | L19: =SUMIFS('GL Data'!$N:$N,'GL Data'!$B:$B,$A19) -> 1072.85 | M19: =SUMIFS('GL Data'!$O:$O,'GL Data'!$B:$B,$A19) -> 617.86 | N19: =SUMIFS('GL Data'!$P:$P,'GL Data'!$B:$B,$A19) -> 534.89 | O19: =SUMIFS('GL Data'!$Q:$Q,'GL Data'!$B:$B,$A19) -> 732.63 | P19: =SUMIFS('GL Data'!$R:$R,'GL Data'!$B:$B,$A19) -> 1252.22 | Q19: =SUMIFS('GL Data'!$S:$S,'GL Data'!$B:$B,$A19) -> 1004.05 | R19: =SUMIFS('GL Data'!$T:$T,'GL Data'!$B:$B,$A19) -> 1130.93 | S19: =SUMIFS('GL Data'!$U:$U,'GL Data'!$B:$B,$A19) -> 974.1 | T19: =SUMIFS('GL Data'!$V:$V,'GL Data'!$B:$B,$A19) -> 1300.18 | U19: =SUMIFS('GL Data'!$W:$W,'GL Data'!$B:$B,$A19) -> 1260.22 | V19: =SUMIFS('GL Data'!$X:$X,'GL Data'!$B:$B,$A19) -> 1062.81 | W19: =SUMIFS('GL Data'!$Y:$Y,'GL Data'!$B:$B,$A19) -> 1311.04 | X19: =SUMIFS('GL Data'!$Z:$Z,'GL Data'!$B:$B,$A19) -> 1443.68 | Y19: =SUMIFS('GL Data'!$AA:$AA,'GL Data'!$B:$B,$A19) -> 1059.39 | Z19: =SUMIFS('GL Data'!$AB:$AB,'GL Data'!$B:$B,$A19) -> 1295.65 | AA19: =SUMIFS('GL Data'!$AC:$AC,'GL Data'!$B:$B,$A19) -> 701.82
A20: Contractors - Others | C20: =SUMIFS('GL Data'!$E:$E,'GL Data'!$B:$B,$A20) -> 7834.29 | D20: =SUMIFS('GL Data'!$F:$F,'GL Data'!$B:$B,$A20) -> 6064.7 | E20: =SUMIFS('GL Data'!$G:$G,'GL Data'!$B:$B,$A20) -> 4091.34 | F20: =SUMIFS('GL Data'!$H:$H,'GL Data'!$B:$B,$A20) -> 3818.86 | G20: =SUMIFS('GL Data'!$I:$I,'GL Data'!$B:$B,$A20) -> 3589.5 | H20: =SUMIFS('GL Data'!$J:$J,'GL Data'!$B:$B,$A20) -> 3313.24 | I20: =SUMIFS('GL Data'!$K:$K,'GL Data'!$B:$B,$A20) -> 3575.32 | J20: =SUMIFS('GL Data'!$L:$L,'GL Data'!$B:$B,$A20) -> 7481.92 | K20: =SUMIFS('GL Data'!$M:$M,'GL Data'!$B:$B,$A20) -> 3575.32 | L20: =SUMIFS('GL Data'!$N:$N,'GL Data'!$B:$B,$A20) -> 2981.41 | M20: =SUMIFS('GL Data'!$O:$O,'GL Data'!$B:$B,$A20) -> 3675.91 | N20: =SUMIFS('GL Data'!$P:$P,'GL Data'!$B:$B,$A20) -> 3134.72 | O20: =SUMIFS('GL Data'!$Q:$Q,'GL Data'!$B:$B,$A20) -> 2707.3 | P20: =SUMIFS('GL Data'!$R:$R,'GL Data'!$B:$B,$A20) -> 2899.91 | Q20: =SUMIFS('GL Data'!$S:$S,'GL Data'!$B:$B,$A20) -> 4162.38 | R20: =SUMIFS('GL Data'!$T:$T,'GL Data'!$B:$B,$A20) -> 3519.64 | S20: =SUMIFS('GL Data'!$U:$U,'GL Data'!$B:$B,$A20) -> 3252.98 | T20: =SUMIFS('GL Data'!$V:$V,'GL Data'!$B:$B,$A20) -> 3797.61 | U20: =SUMIFS('GL Data'!$W:$W,'GL Data'!$B:$B,$A20) -> 4713.44 | V20: =SUMIFS('GL Data'!$X:$X,'GL Data'!$B:$B,$A20) -> 6541.99 | W20: =SUMIFS('GL Data'!$Y:$Y,'GL Data'!$B:$B,$A20) -> 3330.03 | X20: =SUMIFS('GL Data'!$Z:$Z,'GL Data'!$B:$B,$A20) -> 3372.95 | Y20: =SUMIFS('GL Data'!$AA:$AA,'GL Data'!$B:$B,$A20) -> 4847.32 | Z20: =SUMIFS('GL Data'!$AB:$AB,'GL Data'!$B:$B,$A20) -> 3915.98 | AA20: =SUMIFS('GL Data'!$AC:$AC,'GL Data'!$B:$B,$A20) -> 3525.4
A21: VA Incentives | C21: =SUMIFS('GL Data'!$E:$E,'GL Data'!$B:$B,$A21) -> 247.85 | D21: =SUMIFS('GL Data'!$F:$F,'GL Data'!$B:$B,$A21) -> 354.06 | E21: =SUMIFS('GL Data'!$G:$G,'GL Data'!$B:$B,$A21) -> 309.98 | F21: =SUMIFS('GL Data'!$H:$H,'GL Data'!$B:$B,$A21) -> 50.56 | G21: =SUMIFS('GL Data'!$I:$I,'GL Data'!$B:$B,$A21) -> 409.59 | H21: =SUMIFS('GL Data'!$J:$J,'GL Data'!$B:$B,$A21) -> 126.1 | I21: =SUMIFS('GL Data'!$K:$K,'GL Data'!$B:$B,$A21) -> 278.28 | J21: =SUMIFS('GL Data'!$L:$L,'GL Data'!$B:$B,$A21) -> 257.2 | K21: =SUMIFS('GL Data'!$M:$M,'GL Data'!$B:$B,$A21) -> 252.19 | L21: =SUMIFS('GL Data'!$N:$N,'GL Data'!$B:$B,$A21) -> 111.07 | M21: =SUMIFS('GL Data'!$O:$O,'GL Data'!$B:$B,$A21) -> 476.68 | N21: =SUMIFS('GL Data'!$P:$P,'GL Data'!$B:$B,$A21) -> 85.67 | O21: =SUMIFS('GL Data'!$Q:$Q,'GL Data'!$B:$B,$A21) -> 206.89 | P21: =SUMIFS('GL Data'!$R:$R,'GL Data'!$B:$B,$A21) -> 714.82 | Q21: =SUMIFS('GL Data'!$S:$S,'GL Data'!$B:$B,$A21) -> 297.3 | R21: =SUMIFS('GL Data'!$T:$T,'GL Data'!$B:$B,$A21) -> 105.81 | S21: =SUMIFS('GL Data'!$U:$U,'GL Data'!$B:$B,$A21) -> 472.45 | T21: =SUMIFS('GL Data'!$V:$V,'GL Data'!$B:$B,$A21) -> 242.07 | U21: =SUMIFS('GL Data'!$W:$W,'GL Data'!$B:$B,$A21) -> 140.88 | V21: =SUMIFS('GL Data'!$X:$X,'GL Data'!$B:$B,$A21) -> 466.66 | W21: =SUMIFS('GL Data'!$Y:$Y,'GL Data'!$B:$B,$A21) -> 302.49 | X21: =SUMIFS('GL Data'!$Z:$Z,'GL Data'!$B:$B,$A21) -> 116.64 | Y21: =SUMIFS('GL Data'!$AA:$AA,'GL Data'!$B:$B,$A21) -> 711.88 | Z21: =SUMIFS('GL Data'!$AB:$AB,'GL Data'!$B:$B,$A21) -> 157.59 | AA21: =SUMIFS('GL Data'!$AC:$AC,'GL Data'!$B:$B,$A21) -> 236.81
A22: Total Cost of Services | C22: =SUM(C18:C21) -> 28642.54 | D22: =SUM(D18:D21) -> 25502.58 | E22: =SUM(E18:E21) -> 26216.35 | F22: =SUM(F18:F21) -> 25355.54 | G22: =SUM(G18:G21) -> 27015.86 | H22: =SUM(H18:H21) -> 26836.6 | I22: =SUM(I18:I21) -> 23833.71 | J22: =SUM(J18:J21) -> 26045.68 | ... AA22: =SUM(AA18:AA21) -> 26722.78
A23: Gross Profit | C23: =C15-C22 -> 36877 | D23: =D15-D22 -> 53054.89 | E23: =E15-E22 -> 43228.55 | F23: =F15-F22 -> 44064.78 | G23: =G15-G22 -> 47586.8 | H23: =H15-H22 -> 42717.98 | I23: =I15-I22 -> 44468.64 | J23: =J15-J22 -> 39539.74 | ... AA23: =AA15-AA22 -> 37404.44
A24: Gross Margin % | C24: =IFERROR(C23/C15,0) -> 0.56283973 | D24: =IFERROR(D23/D15,0) -> 0.67536404 | E24: =IFERROR(E23/E15,0) -> 0.62248704 | F24: =IFERROR(F23/F15,0) -> 0.63475334 | G24: =IFERROR(G23/G15,0) -> 0.63787002 | H24: =IFERROR(H23/H15,0) -> 0.61416488 | I24: =IFERROR(I23/I15,0) -> 0.65105578 | J24: =IFERROR(J23/J15,0) -> 0.60287393 | ... AA24: =IFERROR(AA23/AA15,0) -> 0.58328491
A26: Operating Expenses
A27: Marketing Expenses
A28: Advertising & Marketing | C28: =SUMIFS('GL Data'!$E:$E,'GL Data'!$B:$B,$A28) -> 827.45 | D28: =SUMIFS('GL Data'!$F:$F,'GL Data'!$B:$B,$A28) -> 825.18 | E28: =SUMIFS('GL Data'!$G:$G,'GL Data'!$B:$B,$A28) -> 1047.16 | F28: =SUMIFS('GL Data'!$H:$H,'GL Data'!$B:$B,$A28) -> 1019.82 | G28: =SUMIFS('GL Data'!$I:$I,'GL Data'!$B:$B,$A28) -> 771 | H28: =SUMIFS('GL Data'!$J:$J,'GL Data'!$B:$B,$A28) -> 949.58 | I28: =SUMIFS('GL Data'!$K:$K,'GL Data'!$B:$B,$A28) -> 1154.99 | J28: =SUMIFS('GL Data'!$L:$L,'GL Data'!$B:$B,$A28) -> 426.1 | K28: =SUMIFS('GL Data'!$M:$M,'GL Data'!$B:$B,$A28) -> 397.46 | L28: =SUMIFS('GL Data'!$N:$N,'GL Data'!$B:$B,$A28) -> 263.93 | M28: =SUMIFS('GL Data'!$O:$O,'GL Data'!$B:$B,$A28) -> 454.09 | N28: =SUMIFS('GL Data'!$P:$P,'GL Data'!$B:$B,$A28) -> 437.04 | O28: =SUMIFS('GL Data'!$Q:$Q,'GL Data'!$B:$B,$A28) -> 836.91 | P28: =SUMIFS('GL Data'!$R:$R,'GL Data'!$B:$B,$A28) -> 586.22 | Q28: =SUMIFS('GL Data'!$S:$S,'GL Data'!$B:$B,$A28) -> 359.35 | R28: =SUMIFS('GL Data'!$T:$T,'GL Data'!$B:$B,$A28) -> 488.99 | S28: =SUMIFS('GL Data'!$U:$U,'GL Data'!$B:$B,$A28) -> 466.09 | T28: =SUMIFS('GL Data'!$V:$V,'GL Data'!$B:$B,$A28) -> 608.78 | U28: =SUMIFS('GL Data'!$W:$W,'GL Data'!$B:$B,$A28) -> 552.84 | V28: =SUMIFS('GL Data'!$X:$X,'GL Data'!$B:$B,$A28) -> 412.8 | W28: =SUMIFS('GL Data'!$Y:$Y,'GL Data'!$B:$B,$A28) -> 357.41 | X28: =SUMIFS('GL Data'!$Z:$Z,'GL Data'!$B:$B,$A28) -> 615.57 | Y28: =SUMIFS('GL Data'!$AA:$AA,'GL Data'!$B:$B,$A28) -> 548.07 | Z28: =SUMIFS('GL Data'!$AB:$AB,'GL Data'!$B:$B,$A28) -> 583.71 | AA28: =SUMIFS('GL Data'!$AC:$AC,'GL Data'!$B:$B,$A28) -> 792.14
A29: Marketing Softwares | C29: =SUMIFS('GL Data'!$E:$E,'GL Data'!$B:$B,$A29) -> 662.09 | D29: =SUMIFS('GL Data'!$F:$F,'GL Data'!$B:$B,$A29) -> 236.68 | E29: =SUMIFS('GL Data'!$G:$G,'GL Data'!$B:$B,$A29) -> 279.23 | F29: =SUMIFS('GL Data'!$H:$H,'GL Data'!$B:$B,$A29) -> 340.67 | G29: =SUMIFS('GL Data'!$I:$I,'GL Data'!$B:$B,$A29) -> 277.06 | H29: =SUMIFS('GL Data'!$J:$J,'GL Data'!$B:$B,$A29) -> 212.56 | I29: =SUMIFS('GL Data'!$K:$K,'GL Data'!$B:$B,$A29) -> 332.05 | J29: =SUMIFS('GL Data'!$L:$L,'GL Data'!$B:$B,$A29) -> 291.49 | K29: =SUMIFS('GL Data'!$M:$M,'GL Data'!$B:$B,$A29) -> 341.1 | L29: =SUMIFS('GL Data'!$N:$N,'GL Data'!$B:$B,$A29) -> 250.37 | M29: =SUMIFS('GL Data'!$O:$O,'GL Data'!$B:$B,$A29) -> 245.75 | N29: =SUMIFS('GL Data'!$P:$P,'GL Data'!$B:$B,$A29) -> 380.92 | O29: =SUMIFS('GL Data'!$Q:$Q,'GL Data'!$B:$B,$A29) -> 645.24 | P29: =SUMIFS('GL Data'!$R:$R,'GL Data'!$B:$B,$A29) -> 315.52 | Q29: =SUMIFS('GL Data'!$S:$S,'GL Data'!$B:$B,$A29) -> 299.58 | R29: =SUMIFS('GL Data'!$T:$T,'GL Data'!$B:$B,$A29) -> 304.11 | S29: =SUMIFS('GL Data'!$U:$U,'GL Data'!$B:$B,$A29) -> 313.11 | T29: =SUMIFS('GL Data'!$V:$V,'GL Data'!$B:$B,$A29) -> 280.1 | U29: =SUMIFS('GL Data'!$W:$W,'GL Data'!$B:$B,$A29) -> 938.9 | V29: =SUMIFS('GL Data'!$X:$X,'GL Data'!$B:$B,$A29) -> -156 | W29: =SUMIFS('GL Data'!$Y:$Y,'GL Data'!$B:$B,$A29) -> 301.55 | X29: =SUMIFS('GL Data'!$Z:$Z,'GL Data'!$B:$B,$A29) -> 364.83 | Y29: =SUMIFS('GL Data'!$AA:$AA,'GL Data'!$B:$B,$A29) -> 301.55 | Z29: =SUMIFS('GL Data'!$AB:$AB,'GL Data'!$B:$B,$A29) -> 270.51 | AA29: =SUMIFS('GL Data'!$AC:$AC,'GL Data'!$B:$B,$A29) -> 647.3
A30: Marketing Subscriptions | C30: =SUMIFS('GL Data'!$E:$E,'GL Data'!$B:$B,$A30) -> 0 | D30: =SUMIFS('GL Data'!$F:$F,'GL Data'!$B:$B,$A30) -> 0 | E30: =SUMIFS('GL Data'!$G:$G,'GL Data'!$B:$B,$A30) -> 0 | F30: =SUMIFS('GL Data'!$H:$H,'GL Data'!$B:$B,$A30) -> 0 | G30: =SUMIFS('GL Data'!$I:$I,'GL Data'!$B:$B,$A30) -> 0 | H30: =SUMIFS('GL Data'!$J:$J,'GL Data'!$B:$B,$A30) -> 0 | I30: =SUMIFS('GL Data'!$K:$K,'GL Data'!$B:$B,$A30) -> 0 | J30: =SUMIFS('GL Data'!$L:$L,'GL Data'!$B:$B,$A30) -> 0 | K30: =SUMIFS('GL Data'!$M:$M,'GL Data'!$B:$B,$A30) -> 0 | L30: =SUMIFS('GL Data'!$N:$N,'GL Data'!$B:$B,$A30) -> 0 | M30: =SUMIFS('GL Data'!$O:$O,'GL Data'!$B:$B,$A30) -> 0 | N30: =SUMIFS('GL Data'!$P:$P,'GL Data'!$B:$B,$A30) -> 0 | O30: =SUMIFS('GL Data'!$Q:$Q,'GL Data'!$B:$B,$A30) -> 0 | P30: =SUMIFS('GL Data'!$R:$R,'GL Data'!$B:$B,$A30) -> 0 | Q30: =SUMIFS('GL Data'!$S:$S,'GL Data'!$B:$B,$A30) -> 0 | R30: =SUMIFS('GL Data'!$T:$T,'GL Data'!$B:$B,$A30) -> 0 | S30: =SUMIFS('GL Data'!$U:$U,'GL Data'!$B:$B,$A30) -> 0 | T30: =SUMIFS('GL Data'!$V:$V,'GL Data'!$B:$B,$A30) -> 0 | U30: =SUMIFS('GL Data'!$W:$W,'GL Data'!$B:$B,$A30) -> 97 | V30: =SUMIFS('GL Data'!$X:$X,'GL Data'!$B:$B,$A30) -> 0 | W30: =SUMIFS('GL Data'!$Y:$Y,'GL Data'!$B:$B,$A30) -> 0 | X30: =SUMIFS('GL Data'!$Z:$Z,'GL Data'!$B:$B,$A30) -> 0 | Y30: =SUMIFS('GL Data'!$AA:$AA,'GL Data'!$B:$B,$A30) -> 0 | Z30: =SUMIFS('GL Data'!$AB:$AB,'GL Data'!$B:$B,$A30) -> 0 | AA30: =SUMIFS('GL Data'!$AC:$AC,'GL Data'!$B:$B,$A30) -> 3.46
A31: VA Pay - Marketing | C31: =SUMIFS('GL Data'!$E:$E,'GL Data'!$B:$B,$A31) -> 4510.08 | D31: =SUMIFS('GL Data'!$F:$F,'GL Data'!$B:$B,$A31) -> 4160.89 | E31: =SUMIFS('GL Data'!$G:$G,'GL Data'!$B:$B,$A31) -> 4387.96 | F31: =SUMIFS('GL Data'!$H:$H,'GL Data'!$B:$B,$A31) -> 3850.96 | G31: =SUMIFS('GL Data'!$I:$I,'GL Data'!$B:$B,$A31) -> 4025.92 | H31: =SUMIFS('GL Data'!$J:$J,'GL Data'!$B:$B,$A31) -> 3198.27 | I31: =SUMIFS('GL Data'!$K:$K,'GL Data'!$B:$B,$A31) -> 2695.19 | J31: =SUMIFS('GL Data'!$L:$L,'GL Data'!$B:$B,$A31) -> 2513.97 | K31: =SUMIFS('GL Data'!$M:$M,'GL Data'!$B:$B,$A31) -> 3010.22 | L31: =SUMIFS('GL Data'!$N:$N,'GL Data'!$B:$B,$A31) -> 2861.52 | M31: =SUMIFS('GL Data'!$O:$O,'GL Data'!$B:$B,$A31) -> 2868.74 | N31: =SUMIFS('GL Data'!$P:$P,'GL Data'!$B:$B,$A31) -> 3063.17 | O31: =SUMIFS('GL Data'!$Q:$Q,'GL Data'!$B:$B,$A31) -> 3158.78 | P31: =SUMIFS('GL Data'!$R:$R,'GL Data'!$B:$B,$A31) -> 3552.28 | Q31: =SUMIFS('GL Data'!$S:$S,'GL Data'!$B:$B,$A31) -> 3706.08 | R31: =SUMIFS('GL Data'!$T:$T,'GL Data'!$B:$B,$A31) -> 2873.17 | S31: =SUMIFS('GL Data'!$U:$U,'GL Data'!$B:$B,$A31) -> 3028.44 | T31: =SUMIFS('GL Data'!$V:$V,'GL Data'!$B:$B,$A31) -> 3159.05 | U31: =SUMIFS('GL Data'!$W:$W,'GL Data'!$B:$B,$A31) -> 3285.06 | V31: =SUMIFS('GL Data'!$X:$X,'GL Data'!$B:$B,$A31) -> 2642.71 | W31: =SUMIFS('GL Data'!$Y:$Y,'GL Data'!$B:$B,$A31) -> 3502.91 | X31: =SUMIFS('GL Data'!$Z:$Z,'GL Data'!$B:$B,$A31) -> 2983.35 | Y31: =SUMIFS('GL Data'!$AA:$AA,'GL Data'!$B:$B,$A31) -> 3467.93 | Z31: =SUMIFS('GL Data'!$AB:$AB,'GL Data'!$B:$B,$A31) -> 3470.88 | AA31: =SUMIFS('GL Data'!$AC:$AC,'GL Data'!$B:$B,$A31) -> 3010.89
A32: Website Fees | C32: =SUMIFS('GL Data'!$E:$E,'GL Data'!$B:$B,$A32) -> 196.32 | D32: =SUMIFS('GL Data'!$F:$F,'GL Data'!$B:$B,$A32) -> 101.81 | E32: =SUMIFS('GL Data'!$G:$G,'GL Data'!$B:$B,$A32) -> 101.81 | F32: =SUMIFS('GL Data'!$H:$H,'GL Data'!$B:$B,$A32) -> 110.39 | G32: =SUMIFS('GL Data'!$I:$I,'GL Data'!$B:$B,$A32) -> 110.39 | H32: =SUMIFS('GL Data'!$J:$J,'GL Data'!$B:$B,$A32) -> 360.65 | I32: =SUMIFS('GL Data'!$K:$K,'GL Data'!$B:$B,$A32) -> 176.9 | J32: =SUMIFS('GL Data'!$L:$L,'GL Data'!$B:$B,$A32) -> 132.56 | K32: =SUMIFS('GL Data'!$M:$M,'GL Data'!$B:$B,$A32) -> 110.39 | L32: =SUMIFS('GL Data'!$N:$N,'GL Data'!$B:$B,$A32) -> 110.39 | M32: =SUMIFS('GL Data'!$O:$O,'GL Data'!$B:$B,$A32) -> 110.39 | N32: =SUMIFS('GL Data'!$P:$P,'GL Data'!$B:$B,$A32) -> 134.7 | O32: =SUMIFS('GL Data'!$Q:$Q,'GL Data'!$B:$B,$A32) -> 156.87 | P32: =SUMIFS('GL Data'!$R:$R,'GL Data'!$B:$B,$A32) -> 112.53 | Q32: =SUMIFS('GL Data'!$S:$S,'GL Data'!$B:$B,$A32) -> 112.53 | R32: =SUMIFS('GL Data'!$T:$T,'GL Data'!$B:$B,$A32) -> 112.53 | S32: =SUMIFS('GL Data'!$U:$U,'GL Data'!$B:$B,$A32) -> 112.53 | T32: =SUMIFS('GL Data'!$V:$V,'GL Data'!$B:$B,$A32) -> 318.45 | U32: =SUMIFS('GL Data'!$W:$W,'GL Data'!$B:$B,$A32) -> 112.53 | V32: =SUMIFS('GL Data'!$X:$X,'GL Data'!$B:$B,$A32) -> 112.53 | W32: =SUMIFS('GL Data'!$Y:$Y,'GL Data'!$B:$B,$A32) -> 112.53 | X32: =SUMIFS('GL Data'!$Z:$Z,'GL Data'!$B:$B,$A32) -> 112.53 | Y32: =SUMIFS('GL Data'!$AA:$AA,'GL Data'!$B:$B,$A32) -> 112.53 | Z32: =SUMIFS('GL Data'!$AB:$AB,'GL Data'!$B:$B,$A32) -> 138.5 | AA32: =SUMIFS('GL Data'!$AC:$AC,'GL Data'!$B:$B,$A32) -> 112.53
A33: Total Marketing Expenses | C33: =SUM(C28:C32) -> 6195.94 | D33: =SUM(D28:D32) -> 5324.56 | E33: =SUM(E28:E32) -> 5816.16 | F33: =SUM(F28:F32) -> 5321.84 | G33: =SUM(G28:G32) -> 5184.37 | H33: =SUM(H28:H32) -> 4721.06 | I33: =SUM(I28:I32) -> 4359.13 | J33: =SUM(J28:J32) -> 3364.12 | ... AA33: =SUM(AA28:AA32) -> 4566.32
A35: Personnel & Leadership
A36: OPS Team - Basic | C36: =SUMIFS('GL Data'!$E:$E,'GL Data'!$B:$B,$A36) -> 11779.55 | D36: =SUMIFS('GL Data'!$F:$F,'GL Data'!$B:$B,$A36) -> 12032.11 | E36: =SUMIFS('GL Data'!$G:$G,'GL Data'!$B:$B,$A36) -> 15357.32 | F36: =SUMIFS('GL Data'!$H:$H,'GL Data'!$B:$B,$A36) -> 14044.21 | G36: =SUMIFS('GL Data'!$I:$I,'GL Data'!$B:$B,$A36) -> 14640.15 | H36: =SUMIFS('GL Data'!$J:$J,'GL Data'!$B:$B,$A36) -> 15409.31 | I36: =SUMIFS('GL Data'!$K:$K,'GL Data'!$B:$B,$A36) -> 12769.29 | J36: =SUMIFS('GL Data'!$L:$L,'GL Data'!$B:$B,$A36) -> 11111.23 | K36: =SUMIFS('GL Data'!$M:$M,'GL Data'!$B:$B,$A36) -> 12139.79 | L36: =SUMIFS('GL Data'!$N:$N,'GL Data'!$B:$B,$A36) -> 10917.12 | M36: =SUMIFS('GL Data'!$O:$O,'GL Data'!$B:$B,$A36) -> 10277.49 | N36: =SUMIFS('GL Data'!$P:$P,'GL Data'!$B:$B,$A36) -> 11593.37 | O36: =SUMIFS('GL Data'!$Q:$Q,'GL Data'!$B:$B,$A36) -> 9872.63 | P36: =SUMIFS('GL Data'!$R:$R,'GL Data'!$B:$B,$A36) -> 12363.8 | Q36: =SUMIFS('GL Data'!$S:$S,'GL Data'!$B:$B,$A36) -> 13595.44 | R36: =SUMIFS('GL Data'!$T:$T,'GL Data'!$B:$B,$A36) -> 11428.59 | S36: =SUMIFS('GL Data'!$U:$U,'GL Data'!$B:$B,$A36) -> 11668.9 | T36: =SUMIFS('GL Data'!$V:$V,'GL Data'!$B:$B,$A36) -> 11286.92 | U36: =SUMIFS('GL Data'!$W:$W,'GL Data'!$B:$B,$A36) -> 11367.44 | V36: =SUMIFS('GL Data'!$X:$X,'GL Data'!$B:$B,$A36) -> 11782.14 | W36: =SUMIFS('GL Data'!$Y:$Y,'GL Data'!$B:$B,$A36) -> 12915.24 | X36: =SUMIFS('GL Data'!$Z:$Z,'GL Data'!$B:$B,$A36) -> 11808.97 | Y36: =SUMIFS('GL Data'!$AA:$AA,'GL Data'!$B:$B,$A36) -> 12966.78 | Z36: =SUMIFS('GL Data'!$AB:$AB,'GL Data'!$B:$B,$A36) -> 11805.14 | AA36: =SUMIFS('GL Data'!$AC:$AC,'GL Data'!$B:$B,$A36) -> 12508.21
A37: OPS Team - Other Benefits | C37: =SUMIFS('GL Data'!$E:$E,'GL Data'!$B:$B,$A37) -> 1490.14 | D37: =SUMIFS('GL Data'!$F:$F,'GL Data'!$B:$B,$A37) -> 1563.68 | E37: =SUMIFS('GL Data'!$G:$G,'GL Data'!$B:$B,$A37) -> 1827.66 | F37: =SUMIFS('GL Data'!$H:$H,'GL Data'!$B:$B,$A37) -> 2332.16 | G37: =SUMIFS('GL Data'!$I:$I,'GL Data'!$B:$B,$A37) -> 3929.96 | H37: =SUMIFS('GL Data'!$J:$J,'GL Data'!$B:$B,$A37) -> 2043.02 | I37: =SUMIFS('GL Data'!$K:$K,'GL Data'!$B:$B,$A37) -> 1038.37 | J37: =SUMIFS('GL Data'!$L:$L,'GL Data'!$B:$B,$A37) -> 5453.48 | K37: =SUMIFS('GL Data'!$M:$M,'GL Data'!$B:$B,$A37) -> 3421.45 | L37: =SUMIFS('GL Data'!$N:$N,'GL Data'!$B:$B,$A37) -> 2730.7 | M37: =SUMIFS('GL Data'!$O:$O,'GL Data'!$B:$B,$A37) -> 3818.62 | N37: =SUMIFS('GL Data'!$P:$P,'GL Data'!$B:$B,$A37) -> 1910.73 | O37: =SUMIFS('GL Data'!$Q:$Q,'GL Data'!$B:$B,$A37) -> 2083.84 | P37: =SUMIFS('GL Data'!$R:$R,'GL Data'!$B:$B,$A37) -> 1658.96 | Q37: =SUMIFS('GL Data'!$S:$S,'GL Data'!$B:$B,$A37) -> 946.53 | R37: =SUMIFS('GL Data'!$T:$T,'GL Data'!$B:$B,$A37) -> 2249.35 | S37: =SUMIFS('GL Data'!$U:$U,'GL Data'!$B:$B,$A37) -> 2621.64 | T37: =SUMIFS('GL Data'!$V:$V,'GL Data'!$B:$B,$A37) -> 2197.01 | U37: =SUMIFS('GL Data'!$W:$W,'GL Data'!$B:$B,$A37) -> 2255.66 | V37: =SUMIFS('GL Data'!$X:$X,'GL Data'!$B:$B,$A37) -> 6460.81 | W37: =SUMIFS('GL Data'!$Y:$Y,'GL Data'!$B:$B,$A37) -> 3284.9 | X37: =SUMIFS('GL Data'!$Z:$Z,'GL Data'!$B:$B,$A37) -> 2781.52 | Y37: =SUMIFS('GL Data'!$AA:$AA,'GL Data'!$B:$B,$A37) -> 2659.46 | Z37: =SUMIFS('GL Data'!$AB:$AB,'GL Data'!$B:$B,$A37) -> 3408.61 | AA37: =SUMIFS('GL Data'!$AC:$AC,'GL Data'!$B:$B,$A37) -> 1917.63
A38: OPS - Incentives | C38: =SUMIFS('GL Data'!$E:$E,'GL Data'!$B:$B,$A38) -> 116.69 | D38: =SUMIFS('GL Data'!$F:$F,'GL Data'!$B:$B,$A38) -> 1832.08 | E38: =SUMIFS('GL Data'!$G:$G,'GL Data'!$B:$B,$A38) -> 200.16 | F38: =SUMIFS('GL Data'!$H:$H,'GL Data'!$B:$B,$A38) -> 203.75 | G38: =SUMIFS('GL Data'!$I:$I,'GL Data'!$B:$B,$A38) -> 1767.49 | H38: =SUMIFS('GL Data'!$J:$J,'GL Data'!$B:$B,$A38) -> 160.09 | I38: =SUMIFS('GL Data'!$K:$K,'GL Data'!$B:$B,$A38) -> 68.64 | J38: =SUMIFS('GL Data'!$L:$L,'GL Data'!$B:$B,$A38) -> 1110.8 | K38: =SUMIFS('GL Data'!$M:$M,'GL Data'!$B:$B,$A38) -> 43.53 | L38: =SUMIFS('GL Data'!$N:$N,'GL Data'!$B:$B,$A38) -> 193.3 | M38: =SUMIFS('GL Data'!$O:$O,'GL Data'!$B:$B,$A38) -> 1150.33 | N38: =SUMIFS('GL Data'!$P:$P,'GL Data'!$B:$B,$A38) -> 54.35 | O38: =SUMIFS('GL Data'!$Q:$Q,'GL Data'!$B:$B,$A38) -> 78.76 | P38: =SUMIFS('GL Data'!$R:$R,'GL Data'!$B:$B,$A38) -> 1347.09 | Q38: =SUMIFS('GL Data'!$S:$S,'GL Data'!$B:$B,$A38) -> 150.44 | R38: =SUMIFS('GL Data'!$T:$T,'GL Data'!$B:$B,$A38) -> 119.76 | S38: =SUMIFS('GL Data'!$U:$U,'GL Data'!$B:$B,$A38) -> 1783.78 | T38: =SUMIFS('GL Data'!$V:$V,'GL Data'!$B:$B,$A38) -> 82.18 | U38: =SUMIFS('GL Data'!$W:$W,'GL Data'!$B:$B,$A38) -> 152.4 | V38: =SUMIFS('GL Data'!$X:$X,'GL Data'!$B:$B,$A38) -> 1741.25 | W38: =SUMIFS('GL Data'!$Y:$Y,'GL Data'!$B:$B,$A38) -> 320.65 | X38: =SUMIFS('GL Data'!$Z:$Z,'GL Data'!$B:$B,$A38) -> 152.34 | Y38: =SUMIFS('GL Data'!$AA:$AA,'GL Data'!$B:$B,$A38) -> 1454.05 | Z38: =SUMIFS('GL Data'!$AB:$AB,'GL Data'!$B:$B,$A38) -> 309.75 | AA38: =SUMIFS('GL Data'!$AC:$AC,'GL Data'!$B:$B,$A38) -> 427.85
A39: Salaries and Wages | C39: =SUMIFS('GL Data'!$E:$E,'GL Data'!$B:$B,$A39) -> 3601.58 | D39: =SUMIFS('GL Data'!$F:$F,'GL Data'!$B:$B,$A39) -> 2851.58 | E39: =SUMIFS('GL Data'!$G:$G,'GL Data'!$B:$B,$A39) -> 2101.58 | F39: =SUMIFS('GL Data'!$H:$H,'GL Data'!$B:$B,$A39) -> 2101.58 | G39: =SUMIFS('GL Data'!$I:$I,'GL Data'!$B:$B,$A39) -> 2101.58 | H39: =SUMIFS('GL Data'!$J:$J,'GL Data'!$B:$B,$A39) -> 2101.58 | I39: =SUMIFS('GL Data'!$K:$K,'GL Data'!$B:$B,$A39) -> 2101.58 | J39: =SUMIFS('GL Data'!$L:$L,'GL Data'!$B:$B,$A39) -> 2101.58 | K39: =SUMIFS('GL Data'!$M:$M,'GL Data'!$B:$B,$A39) -> 2101.58 | L39: =SUMIFS('GL Data'!$N:$N,'GL Data'!$B:$B,$A39) -> 2101.58 | M39: =SUMIFS('GL Data'!$O:$O,'GL Data'!$B:$B,$A39) -> 2101.58 | N39: =SUMIFS('GL Data'!$P:$P,'GL Data'!$B:$B,$A39) -> 2101.58 | O39: =SUMIFS('GL Data'!$Q:$Q,'GL Data'!$B:$B,$A39) -> 2101.58 | P39: =SUMIFS('GL Data'!$R:$R,'GL Data'!$B:$B,$A39) -> 2101.58 | Q39: =SUMIFS('GL Data'!$S:$S,'GL Data'!$B:$B,$A39) -> 2101.58 | R39: =SUMIFS('GL Data'!$T:$T,'GL Data'!$B:$B,$A39) -> 2101.58 | S39: =SUMIFS('GL Data'!$U:$U,'GL Data'!$B:$B,$A39) -> 2101.59 | T39: =SUMIFS('GL Data'!$V:$V,'GL Data'!$B:$B,$A39) -> 2101.58 | U39: =SUMIFS('GL Data'!$W:$W,'GL Data'!$B:$B,$A39) -> 2101.58 | V39: =SUMIFS('GL Data'!$X:$X,'GL Data'!$B:$B,$A39) -> 2101.58 | W39: =SUMIFS('GL Data'!$Y:$Y,'GL Data'!$B:$B,$A39) -> 2101.58 | X39: =SUMIFS('GL Data'!$Z:$Z,'GL Data'!$B:$B,$A39) -> 2101.58 | Y39: =SUMIFS('GL Data'!$AA:$AA,'GL Data'!$B:$B,$A39) -> 2101.58 | Z39: =SUMIFS('GL Data'!$AB:$AB,'GL Data'!$B:$B,$A39) -> 2101.58 | AA39: =SUMIFS('GL Data'!$AC:$AC,'GL Data'!$B:$B,$A39) -> 2101.58
A40: Owner's Pay | C40: =SUMIFS('GL Data'!$E:$E,'GL Data'!$B:$B,$A40) -> 3564.92 | D40: =SUMIFS('GL Data'!$F:$F,'GL Data'!$B:$B,$A40) -> 3564.92 | E40: =SUMIFS('GL Data'!$G:$G,'GL Data'!$B:$B,$A40) -> 3564.92 | F40: =SUMIFS('GL Data'!$H:$H,'GL Data'!$B:$B,$A40) -> 3564.92 | G40: =SUMIFS('GL Data'!$I:$I,'GL Data'!$B:$B,$A40) -> 3564.92 | H40: =SUMIFS('GL Data'!$J:$J,'GL Data'!$B:$B,$A40) -> 3564.92 | I40: =SUMIFS('GL Data'!$K:$K,'GL Data'!$B:$B,$A40) -> 3564.92 | J40: =SUMIFS('GL Data'!$L:$L,'GL Data'!$B:$B,$A40) -> 3564.92 | K40: =SUMIFS('GL Data'!$M:$M,'GL Data'!$B:$B,$A40) -> 3564.92 | L40: =SUMIFS('GL Data'!$N:$N,'GL Data'!$B:$B,$A40) -> 3564.92 | M40: =SUMIFS('GL Data'!$O:$O,'GL Data'!$B:$B,$A40) -> 3564.92 | N40: =SUMIFS('GL Data'!$P:$P,'GL Data'!$B:$B,$A40) -> 3564.92 | O40: =SUMIFS('GL Data'!$Q:$Q,'GL Data'!$B:$B,$A40) -> 3564.92 | P40: =SUMIFS('GL Data'!$R:$R,'GL Data'!$B:$B,$A40) -> 3564.92 | Q40: =SUMIFS('GL Data'!$S:$S,'GL Data'!$B:$B,$A40) -> 3564.92 | R40: =SUMIFS('GL Data'!$T:$T,'GL Data'!$B:$B,$A40) -> 3564.92 | S40: =SUMIFS('GL Data'!$U:$U,'GL Data'!$B:$B,$A40) -> 3564.91 | T40: =SUMIFS('GL Data'!$V:$V,'GL Data'!$B:$B,$A40) -> 8564.92 | U40: =SUMIFS('GL Data'!$W:$W,'GL Data'!$B:$B,$A40) -> 8564.92 | V40: =SUMIFS('GL Data'!$X:$X,'GL Data'!$B:$B,$A40) -> 5000 | W40: =SUMIFS('GL Data'!$Y:$Y,'GL Data'!$B:$B,$A40) -> 5000 | X40: =SUMIFS('GL Data'!$Z:$Z,'GL Data'!$B:$B,$A40) -> 5000 | Y40: =SUMIFS('GL Data'!$AA:$AA,'GL Data'!$B:$B,$A40) -> 5000 | Z40: =SUMIFS('GL Data'!$AB:$AB,'GL Data'!$B:$B,$A40) -> 5000 | AA40: =SUMIFS('GL Data'!$AC:$AC,'GL Data'!$B:$B,$A40) -> 5000
A41: VA Pay - Smart VA Academy | C41: =SUMIFS('GL Data'!$E:$E,'GL Data'!$B:$B,$A41) -> 590.05 | D41: =SUMIFS('GL Data'!$F:$F,'GL Data'!$B:$B,$A41) -> 437.05 | E41: =SUMIFS('GL Data'!$G:$G,'GL Data'!$B:$B,$A41) -> 565.24 | F41: =SUMIFS('GL Data'!$H:$H,'GL Data'!$B:$B,$A41) -> 481.09 | G41: =SUMIFS('GL Data'!$I:$I,'GL Data'!$B:$B,$A41) -> 396.1 | H41: =SUMIFS('GL Data'!$J:$J,'GL Data'!$B:$B,$A41) -> 529.38 | I41: =SUMIFS('GL Data'!$K:$K,'GL Data'!$B:$B,$A41) -> 441.61 | J41: =SUMIFS('GL Data'!$L:$L,'GL Data'!$B:$B,$A41) -> 37.38 | K41: =SUMIFS('GL Data'!$M:$M,'GL Data'!$B:$B,$A41) -> 336.95 | L41: =SUMIFS('GL Data'!$N:$N,'GL Data'!$B:$B,$A41) -> 137.89 | M41: =SUMIFS('GL Data'!$O:$O,'GL Data'!$B:$B,$A41) -> 217.37 | N41: =SUMIFS('GL Data'!$P:$P,'GL Data'!$B:$B,$A41) -> 373.36 | O41: =SUMIFS('GL Data'!$Q:$Q,'GL Data'!$B:$B,$A41) -> 366.36 | P41: =SUMIFS('GL Data'!$R:$R,'GL Data'!$B:$B,$A41) -> 332.1 | Q41: =SUMIFS('GL Data'!$S:$S,'GL Data'!$B:$B,$A41) -> 227.73 | R41: =SUMIFS('GL Data'!$T:$T,'GL Data'!$B:$B,$A41) -> 358.54 | S41: =SUMIFS('GL Data'!$U:$U,'GL Data'!$B:$B,$A41) -> 181.9 | T41: =SUMIFS('GL Data'!$V:$V,'GL Data'!$B:$B,$A41) -> 194.92 | U41: =SUMIFS('GL Data'!$W:$W,'GL Data'!$B:$B,$A41) -> 65.27 | V41: =SUMIFS('GL Data'!$X:$X,'GL Data'!$B:$B,$A41) -> 87.13 | W41: =SUMIFS('GL Data'!$Y:$Y,'GL Data'!$B:$B,$A41) -> 158.24 | X41: =SUMIFS('GL Data'!$Z:$Z,'GL Data'!$B:$B,$A41) -> 62.3 | Y41: =SUMIFS('GL Data'!$AA:$AA,'GL Data'!$B:$B,$A41) -> 106.41 | Z41: =SUMIFS('GL Data'!$AB:$AB,'GL Data'!$B:$B,$A41) -> 2.48 | AA41: =SUMIFS('GL Data'!$AC:$AC,'GL Data'!$B:$B,$A41) -> 0
A42: Retirement Expense | C42: =SUMIFS('GL Data'!$E:$E,'GL Data'!$B:$B,$A42) -> 214.98 | D42: =SUMIFS('GL Data'!$F:$F,'GL Data'!$B:$B,$A42) -> 192.48 | E42: =SUMIFS('GL Data'!$G:$G,'GL Data'!$B:$B,$A42) -> 169.98 | F42: =SUMIFS('GL Data'!$H:$H,'GL Data'!$B:$B,$A42) -> 169.98 | G42: =SUMIFS('GL Data'!$I:$I,'GL Data'!$B:$B,$A42) -> 169.98 | H42: =SUMIFS('GL Data'!$J:$J,'GL Data'!$B:$B,$A42) -> 169.98 | I42: =SUMIFS('GL Data'!$K:$K,'GL Data'!$B:$B,$A42) -> 169.98 | J42: =SUMIFS('GL Data'!$L:$L,'GL Data'!$B:$B,$A42) -> 169.98 | K42: =SUMIFS('GL Data'!$M:$M,'GL Data'!$B:$B,$A42) -> 169.98 | L42: =SUMIFS('GL Data'!$N:$N,'GL Data'!$B:$B,$A42) -> 169.98 | M42: =SUMIFS('GL Data'!$O:$O,'GL Data'!$B:$B,$A42) -> 169.98 | N42: =SUMIFS('GL Data'!$P:$P,'GL Data'!$B:$B,$A42) -> 169.98 | O42: =SUMIFS('GL Data'!$Q:$Q,'GL Data'!$B:$B,$A42) -> 169.98 | P42: =SUMIFS('GL Data'!$R:$R,'GL Data'!$B:$B,$A42) -> 169.98 | Q42: =SUMIFS('GL Data'!$S:$S,'GL Data'!$B:$B,$A42) -> 169.98 | R42: =SUMIFS('GL Data'!$T:$T,'GL Data'!$B:$B,$A42) -> 169.98 | S42: =SUMIFS('GL Data'!$U:$U,'GL Data'!$B:$B,$A42) -> 169.98 | T42: =SUMIFS('GL Data'!$V:$V,'GL Data'!$B:$B,$A42) -> 319.98 | U42: =SUMIFS('GL Data'!$W:$W,'GL Data'!$B:$B,$A42) -> 319.98 | V42: =SUMIFS('GL Data'!$X:$X,'GL Data'!$B:$B,$A42) -> 213.04 | W42: =SUMIFS('GL Data'!$Y:$Y,'GL Data'!$B:$B,$A42) -> 213.04 | X42: =SUMIFS('GL Data'!$Z:$Z,'GL Data'!$B:$B,$A42) -> 213.04 | Y42: =SUMIFS('GL Data'!$AA:$AA,'GL Data'!$B:$B,$A42) -> 213.04 | Z42: =SUMIFS('GL Data'!$AB:$AB,'GL Data'!$B:$B,$A42) -> 213.04 | AA42: =SUMIFS('GL Data'!$AC:$AC,'GL Data'!$B:$B,$A42) -> 213.04
A43: Payroll Tax | C43: =SUMIFS('GL Data'!$E:$E,'GL Data'!$B:$B,$A43) -> 548.24 | D43: =SUMIFS('GL Data'!$F:$F,'GL Data'!$B:$B,$A43) -> 490.87 | E43: =SUMIFS('GL Data'!$G:$G,'GL Data'!$B:$B,$A43) -> 433.5 | F43: =SUMIFS('GL Data'!$H:$H,'GL Data'!$B:$B,$A43) -> 433.5 | G43: =SUMIFS('GL Data'!$I:$I,'GL Data'!$B:$B,$A43) -> 433.5 | H43: =SUMIFS('GL Data'!$J:$J,'GL Data'!$B:$B,$A43) -> 433.5 | I43: =SUMIFS('GL Data'!$K:$K,'GL Data'!$B:$B,$A43) -> 433.5 | J43: =SUMIFS('GL Data'!$L:$L,'GL Data'!$B:$B,$A43) -> 580.82 | K43: =SUMIFS('GL Data'!$M:$M,'GL Data'!$B:$B,$A43) -> 580.05 | L43: =SUMIFS('GL Data'!$N:$N,'GL Data'!$B:$B,$A43) -> 525.54 | M43: =SUMIFS('GL Data'!$O:$O,'GL Data'!$B:$B,$A43) -> 479.71 | N43: =SUMIFS('GL Data'!$P:$P,'GL Data'!$B:$B,$A43) -> 445.37 | O43: =SUMIFS('GL Data'!$Q:$Q,'GL Data'!$B:$B,$A43) -> 433.5 | P43: =SUMIFS('GL Data'!$R:$R,'GL Data'!$B:$B,$A43) -> 433.5 | Q43: =SUMIFS('GL Data'!$S:$S,'GL Data'!$B:$B,$A43) -> 433.5 | R43: =SUMIFS('GL Data'!$T:$T,'GL Data'!$B:$B,$A43) -> 433.5 | S43: =SUMIFS('GL Data'!$U:$U,'GL Data'!$B:$B,$A43) -> 433.5 | T43: =SUMIFS('GL Data'!$V:$V,'GL Data'!$B:$B,$A43) -> 816 | U43: =SUMIFS('GL Data'!$W:$W,'GL Data'!$B:$B,$A43) -> 816 | V43: =SUMIFS('GL Data'!$X:$X,'GL Data'!$B:$B,$A43) -> 727.92 | W43: =SUMIFS('GL Data'!$Y:$Y,'GL Data'!$B:$B,$A43) -> 689.92 | X43: =SUMIFS('GL Data'!$Z:$Z,'GL Data'!$B:$B,$A43) -> 597.92 | Y43: =SUMIFS('GL Data'!$AA:$AA,'GL Data'!$B:$B,$A43) -> 545.97 | Z43: =SUMIFS('GL Data'!$AB:$AB,'GL Data'!$B:$B,$A43) -> 553.67 | AA43: =SUMIFS('GL Data'!$AC:$AC,'GL Data'!$B:$B,$A43) -> 543.28
A44: Employee Appreciation | C44: =SUMIFS('GL Data'!$E:$E,'GL Data'!$B:$B,$A44) -> 142.75 | D44: =SUMIFS('GL Data'!$F:$F,'GL Data'!$B:$B,$A44) -> 39.34 | E44: =SUMIFS('GL Data'!$G:$G,'GL Data'!$B:$B,$A44) -> 89.43 | F44: =SUMIFS('GL Data'!$H:$H,'GL Data'!$B:$B,$A44) -> 268.82 | G44: =SUMIFS('GL Data'!$I:$I,'GL Data'!$B:$B,$A44) -> 0 | H44: =SUMIFS('GL Data'!$J:$J,'GL Data'!$B:$B,$A44) -> 0 | I44: =SUMIFS('GL Data'!$K:$K,'GL Data'!$B:$B,$A44) -> 17967.81 | J44: =SUMIFS('GL Data'!$L:$L,'GL Data'!$B:$B,$A44) -> 0 | K44: =SUMIFS('GL Data'!$M:$M,'GL Data'!$B:$B,$A44) -> 48.47 | L44: =SUMIFS('GL Data'!$N:$N,'GL Data'!$B:$B,$A44) -> 1728.93 | M44: =SUMIFS('GL Data'!$O:$O,'GL Data'!$B:$B,$A44) -> 827.55 | N44: =SUMIFS('GL Data'!$P:$P,'GL Data'!$B:$B,$A44) -> 91.55 | O44: =SUMIFS('GL Data'!$Q:$Q,'GL Data'!$B:$B,$A44) -> 0 | P44: =SUMIFS('GL Data'!$R:$R,'GL Data'!$B:$B,$A44) -> 110.39 | Q44: =SUMIFS('GL Data'!$S:$S,'GL Data'!$B:$B,$A44) -> 85.49 | R44: =SUMIFS('GL Data'!$T:$T,'GL Data'!$B:$B,$A44) -> 0 | S44: =SUMIFS('GL Data'!$U:$U,'GL Data'!$B:$B,$A44) -> 968.74 | T44: =SUMIFS('GL Data'!$V:$V,'GL Data'!$B:$B,$A44) -> 211.24 | U44: =SUMIFS('GL Data'!$W:$W,'GL Data'!$B:$B,$A44) -> 14667.56 | V44: =SUMIFS('GL Data'!$X:$X,'GL Data'!$B:$B,$A44) -> 107.77 | W44: =SUMIFS('GL Data'!$Y:$Y,'GL Data'!$B:$B,$A44) -> 0 | X44: =SUMIFS('GL Data'!$Z:$Z,'GL Data'!$B:$B,$A44) -> 112.41 | Y44: =SUMIFS('GL Data'!$AA:$AA,'GL Data'!$B:$B,$A44) -> 1363.44 | Z44: =SUMIFS('GL Data'!$AB:$AB,'GL Data'!$B:$B,$A44) -> 164.53 | AA44: =SUMIFS('GL Data'!$AC:$AC,'GL Data'!$B:$B,$A44) -> 105.83
...

Sheet QOE Summary
A1: Smart VAs LLC — Quality of Earnings (Lite)
A2: TTM Period: July 2025 – June 2026 | Source: Monthly Financials tab (seller GL)
A3: Scope note: this is a lite QOE built solely from the seller’s GL-derived monthly financials already in this workbook. No customer-level, contract-level, or vendor-invoice detail was available, so revenue concentration and contract-quality testing (normally part of a full QOE) are out of scope here — flagged in Section 5.
A5: 1. REVENUE QUALITY (TTM)
B6: TTM $ | C6: % of Net Revenue
A7: Service Revenue (Core VA Staffing) | B7: =SUM('Monthly Financials'!P9:AA9) -> 975916.59
A8: Smart VA Academy Revenue (Non-Core) | B8: =SUM('Monthly Financials'!P10:AA10) -> 303.46
A9: Less: Discounts | B9: =SUM('Monthly Financials'!P13:AA13) -> -22786.5
A10: Less: Refunds | B10: =SUM('Monthly Financials'!P14:AA14) -> -10760.29
A11: Net Revenue | B11: =B7+B8+B9+B10 -> 942673.26
A12: Service Revenue % of Net Revenue | B12: =B7/B11 -> 1.035265
A13: Academy Revenue % of Net Revenue | B13: =B8/B11 -> 0.0003219143
A14: Discounts + Refunds % of Gross Revenue | B14: =-(B9+B10)/(B7+B8) -> 0.034363963
A15: Revenue is almost entirely recurring Service Revenue on a prepaid/subscription-style collection model (see DSO in Section 4) — a favorable revenue-quality signal. Academy Revenue is immaterial.
A17: 2. ADJUSTED EBITDA BRIDGE (TTM)
B18: TTM $ | C18: % of Net Revenue
A19: Reported EBIT / EBITDA (No Historical D&A — PP&E Fully Depreciated) | B19: =SUM('Monthly Financials'!P72:AA72) -> 159212.13
A20: Reported EBITDA Margin % | B20: =B19/B11 -> 0.16889429
A22: Add: Owner’s Pay (Control-Basis Addback) | B22: =SUM('Monthly Financials'!P40:AA40) -> 61389.51
A23: Add: Home Office Deduction (Personal/Tax-Driven) | B23: =SUM('Monthly Financials'!P61:AA61) -> 6986.8
A24: Add: Charitable Contributions (Discretionary) | B24: =SUM('Monthly Financials'!P59:AA59) -> 900
A25: Core Adjusted EBITDA | B25: =B19+B22+B23+B24 -> 228488.44
A26: Core Adjusted EBITDA Margin % | B26: =B25/B11 -> 0.2423835
A28: Memo: Judgment-Call Items (Not Included Above)
A29: Employee/Client Appreciation is common in labor-intensive, remote-retention-dependent staffing models and arguably a real cost of keeping VAs — shown separately rather than force-classified.
A30: Employee Appreciation | B30: =SUM('Monthly Financials'!P44:AA44) -> 17897.4
A31: Client Appreciation | B31: =SUM('Monthly Financials'!P50:AA50) -> 547.61
A32: Adjusted EBITDA Including Judgment Items | B32: =B25+B30+B31 -> 246933.45
A33: Adjusted EBITDA Margin % (Incl. Judgment Items) | B33: =B32/B11 -> 0.2619502
A34: Owner’s Pay is added back on a standard control-basis convention. This lite QOE does not assume a specific replacement-management cost — the buyer-side Assumptions tab already models $60,000 in new Owner Compensation plus a $60,000 new hire, which should be read alongside this bridge, not on top of it.
A36: 3. IMPLIED MULTIPLES AT ASKING PRICE
A37: Asking Price | B37: =Assumptions!E10 -> 540000
A38: Multiple of Reported EBITDA | B38: =IFERROR(B37/B19,0) -> 3.3917014
A39: Multiple of Core Adjusted EBITDA | B39: =IFERROR(B37/B25,0) -> 2.3633581
A40: Multiple of Adjusted EBITDA (Incl. Judgment Items) | B40: =IFERROR(B37/B32,0) -> 2.186824
A42: 4. BALANCE SHEET / WORKING CAPITAL QUALITY (as of Jun-2026)
A43: Accounts Receivable | B43: ='Monthly Financials'!AA92 -> 656.25
A44: Days Sales Outstanding (3-Month Rolling) | B44: ='Monthly Financials'!AA293 -> 0.25957164
A45: Net Working Capital, Ex-Cash | B45: ='Monthly Financials'!AA286 -> -4934.83
A46: Fixed Assets, Net Book Value | B46: ='Monthly Financials'!AA303 -> 0
...

Sheet Assumptions
A1: Smart VAs LLC — Acquisition Model
A2: Buyer-Side Transaction, Financing & Operating Assumptions
A3: Currency: USD, whole dollars. Historical baseline ("TTM") figures link live to the Monthly Financials tab (trailing twelve months, Jul-2025–Jun-2026).
A5: ACTIVE SCENARIO (drives the Projections tab): | C5: Base | D5: ← choose Worst / Base / Best
A7: 1. TRANSACTION STRUCTURE & FINANCING
B8: Worst | C8: Base / Value | D8: Best | E8: Selected (Active) | F8: Source / Notes
A9: Deal Terms
A10: Sale (Purchase) Price | B10: =C10 -> 540000 | C10: 540000 | D10: =C10 -> 540000 | E10: =C10 -> 540000 | F10: Per buyer instruction.
A11: Working Capital Injection — % of Sale Price | B11: =C11 -> 0.055555 | C11: 0.055555 | D11: =C11 -> 0.055555 | E11: =C11 -> 0.055555 | F11: Per buyer instruction: cash injected at close for post-close operating buffer.
A12: Working Capital Injection — $ Amount | E12: =E10*E11 -> 29999.7
A13: Total Uses of Funds | E13: =E10+E12 -> 569999.7
A15: Seller Financing (Note) — Dynamically Linked, Set to 0% for Now
A16: Seller Note — % of Sale Price | B16: =C16 -> 0 | C16: 0 | D16: =C16 -> 0 | E16: =C16 -> 0 | F16: Set to 0% pending negotiated terms. Formula-linked to Sale Price so it can be activated by changing this one cell.
A17: Seller Note — $ Amount | E17: =E10*E16 -> 0
A18: Seller Note — Interest Rate | B18: =C18 -> 0.06 | C18: 0.06 | D18: =C18 -> 0.06 | E18: =C18 -> 0.06 | F18: Typical seller-note coupon is 6–8%; immaterial while the note is $0.
A19: Seller Note — Term (Years) | B19: =C19 -> 5 | C19: 5 | D19: =C19 -> 5 | E19: =C19 -> 5
A20: Seller Note — Annual Payment | E20: =IFERROR(-PMT(E18,E19,E17),0) -> 0
A22: Seller Escrow / Indemnity Holdback — 5% Market Convention, Set to 0% for Now
A23: Escrow Retention — % of Sale Price | B23: =C23 -> 0 | C23: 0 | D23: =C23 -> 0 | E23: =C23 -> 0 | F23: Market-standard indemnity holdback is ~5% of price for 12–18 months; set to 0% until deal terms are finalized. Funded from loan/equity proceeds at closing — reduces the seller’s net cash at close only, not Total Uses.
A24: Escrow Amount — $ | E24: =E10*E23 -> 0
A25: Escrow Release Period (Months) | B25: =C25 -> 12 | C25: 12 | D25: =C25 -> 12 | E25: =C25 -> 12
A27: Senior Debt — SBA 7(a) Term Loan
